<?xml version="1.0" ?>
<robot
  name="ugv_rover">
  <link name="base_footprint"></link>

  <!-- Base Link -->
  <link
    name="base_link">
    <inertial>
      <origin
        xyz="-0.000460087791654118 -6.50856019576702E-10 -0.0147959620149623"
        rpy="0 0 0" />
      <mass
        value="2.78375064359473" />
      <inertia
        ixx="0.00651567554169617"
        ixy="-5.86655425789789E-13"
        ixz="3.77886436056975E-05"
        iyy="0.00933991752413667"
        iyz="-2.53116742521487E-11"
        izz="0.0121583506563461" />
    </inertial>
    <visual>
      <origin
        xyz="0 0 0"
        rpy="0 0 0" />
      <geometry>
        <mesh
          filename="package://ugv_description/meshes/ugv_rover/base_link.stl" />
      </geometry>
      <material
        name="">
        <color
          rgba="0.752941176470588 0.752941176470588 0.752941176470588 1" />
      </material>
    </visual>
    <collision>
      <origin
        xyz="0 0 0"
        rpy="0 0 0" />
      <geometry>
        <mesh
          filename="package://ugv_description/meshes/ugv_rover/base_link.stl" />
      </geometry>
    </collision>
  </link>

  <joint name="base_joint" type="fixed">
    <parent link="base_footprint"/>
    <child link="base_link"/>
    <origin xyz="0.000460087791654118 6.50856019576702E-10 0.08" rpy="0 0 0"/> 
  </joint>
  
  <link name="base_imu_link"> 
      <origin xyz="0 0 0" rpy="0 0 0"/> 
  </link>
  
  <joint name="imu_joint" type="fixed">
      <parent link="base_link" />
      <child link="base_imu_link" />
      <origin xyz="0 0 0" rpy="0 0 0"/>
  </joint>

  <!-- Left Up Wheel -->
  <link name="left_up_wheel_link">
    <inertial>
      <origin
        xyz="1.38777878078145E-17 1.38777878078145E-17 0"
        rpy="1.5708 0 0" />
      <mass
        value="0.207085933743005" />
      <inertia
        ixx="0.000116541923504163"
        ixy="-1.59309191113245E-55"
        ixz="-3.43238458333891E-37"
        iyy="0.000170742352371108"
        iyz="-3.6165187302327E-37"
        izz="0.000116541923504163" />
    </inertial>
    <visual>
      <origin
        xyz="0 0 0"
        rpy="1.5708 0 0" />
      <geometry>
        <mesh
          filename="package://ugv_description/meshes/ugv_rover/left_up_wheel_link.stl" />
      </geometry>
      <material
        name="">
        <color
          rgba="0.627450980392157 0.627450980392157 0.627450980392157 1" />
      </material>
    </visual>
    <collision>
      <origin
        xyz="0 0 0"
        rpy="1.5708 0 0" />
      <geometry>
        <mesh
          filename="package://ugv_description/meshes/ugv_rover/left_up_wheel_link.stl" />
      </geometry>
    </collision>
  </link>
  <joint name="left_up_wheel_link_joint" type="continuous">
    <origin xyz="0.0855 0.08726 -0.041212" rpy="1.5708 0 0" />
    <parent link="base_link" />
    <child link="left_up_wheel_link" />
    <axis xyz="0 0 -1" />
  </joint>

  <!-- Left Down Wheel -->
  <link
    name="left_down_wheel_link">
    <inertial>
      <origin
        xyz="0 1.38777878078145E-17 0"
        rpy="1.5708 0 0" />
      <mass
        value="0.207085933743005" />
      <inertia
        ixx="0.000116541923504163"
        ixy="-1.59309191113245E-55"
        ixz="-3.43238458333891E-37"
        iyy="0.000170742352371108"
        iyz="-3.6165187302327E-37"
        izz="0.000116541923504163" />
    </inertial>
    <visual>
      <origin
        xyz="0 0 0"
        rpy="1.5708 0 0" />
      <geometry>
        <mesh
          filename="package://ugv_description/meshes/ugv_rover/left_down_wheel_link.stl" />
      </geometry>
      <material
        name="">
        <color
          rgba="0.627450980392157 0.627450980392157 0.627450980392157 1" />
      </material>
    </visual>
    <collision>
      <origin
        xyz="0 0 0"
        rpy="1.5708 0 0" />
      <geometry>
        <mesh
          filename="package://ugv_description/meshes/ugv_rover/left_down_wheel_link.stl" />
      </geometry>
    </collision>
  </link>
  <joint name="left_down_wheel_link_joint" type="continuous">
    <origin xyz="-0.0855 0.08726 -0.041212" rpy="1.5708 0 0" />
    <parent link="base_link" />
    <child link="left_down_wheel_link" />
    <axis xyz="0 0 -1" />
  </joint>
  <!-- Right Up Wheel -->
  <link
    name="right_up_wheel_link">
    <inertial>
      <origin
        xyz="1.38777878078145E-17 -1.38777878078145E-17 0"
        rpy="1.5708 0 0" />
      <mass
        value="0.207085933743005" />
      <inertia
        ixx="0.000116541923504163"
        ixy="-1.59309191113245E-55"
        ixz="-3.43238458333891E-37"
        iyy="0.000170742352371108"
        iyz="-3.6165187302327E-37"
        izz="0.000116541923504163" />
    </inertial>
    <visual>
      <origin
        xyz="0 0 0"
        rpy="1.5708 0 0" />
      <geometry>
        <mesh
          filename="package://ugv_description/meshes/ugv_rover/right_up_wheel_link.stl" />
      </geometry>
      <material
        name="">
        <color
          rgba="0.627450980392157 0.627450980392157 0.627450980392157 1" />
      </material>
    </visual>
    <collision>
      <origin
        xyz="0 0 0"
        rpy="1.5708 0 0" />
      <geometry>
        <mesh
          filename="package://ugv_description/meshes/ugv_rover/right_up_wheel_link.stl" />
      </geometry>
    </collision>
  </link>
  <joint
    name="right_up_wheel_link_joint"
    type="continuous">
    <origin
      xyz="0.0854999999999989 -0.0872600009999962 -0.0412119912691588"
      rpy="1.5708 0 0" />
    <parent
      link="base_link" />
    <child
      link="right_up_wheel_link" />
    <axis
      xyz="0 0 -1" />
  </joint>

  <!-- Right Down Wheel -->
  <link
    name="right_down_wheel_link">
    <inertial>
      <origin
        xyz="0 -1.38777878078145E-17 0"
        rpy="1.5708 0 0" />
      <mass
        value="0.207085933743005" />
      <inertia
        ixx="0.000116541923504163"
        ixy="-1.59309191113245E-55"
        ixz="-3.43238458333891E-37"
        iyy="0.000170742352371108"
        iyz="-3.6165187302327E-37"
        izz="0.000116541923504163" />
    </inertial>
    <visual>
      <origin
        xyz="0 0 0"
        rpy="1.5708 0 0" />
      <geometry>
        <mesh
          filename="package://ugv_description/meshes/ugv_rover/right_down_wheel_link.stl" />
      </geometry>
      <material
        name="">
        <color
          rgba="0.627450980392157 0.627450980392157 0.627450980392157 1" />
      </material>
    </visual>
    <collision>
      <origin
        xyz="0 0 0"
        rpy="1.5708 0 0" />
      <geometry>
        <mesh
          filename="package://ugv_description/meshes/ugv_rover/right_down_wheel_link.stl" />
      </geometry>
    </collision>
  </link>
  <joint
    name="right_down_wheel_link_joint"
    type="continuous">
    <origin
      xyz="-0.0854999999999981 -0.0872600009999962 -0.0412119912691594"
      rpy="1.5708 0 0" />
    <parent
      link="base_link" />
    <child
      link="right_down_wheel_link" />
    <axis
      xyz="0 0 -1" />
  </joint>
  
  <!-- Base Lidar -->
  <link
    name="base_lidar_link">
    <inertial>
      <origin
        xyz="-6.93889390390723E-18 -1.81372359302323E-18 0.0165546434494574"
        rpy="0 0 0" />
      <mass
        value="0.0418000091653573" />
      <inertia
        ixx="8.26853377699878E-06"
        ixy="-2.32283058129169E-22"
        ixz="-3.51417304718746E-22"
        iyy="8.26853377699876E-06"
        iyz="2.66754484573224E-23"
        izz="8.32524607487378E-06" />
    </inertial>
    <visual>
      <origin
        xyz="0 0 0"
        rpy="0 0 0" />
      <geometry>
        <mesh
          filename="package://ugv_description/meshes/ugv_rover/base_lidar_link.stl" />
      </geometry>
      <material
        name="">
        <color
          rgba="0.627450980392157 0.627450980392157 0.627450980392157 1" />
      </material>
    </visual>
    <collision>
      <origin
        xyz="0 0 0"
        rpy="0 0 0" />
      <geometry>
        <mesh
          filename="package://ugv_description/meshes/ugv_rover/base_lidar_link.stl" />
      </geometry>
    </collision>
  </link>
  <joint
    name="base_lidar_link_joint"
    type="fixed">
    <origin
      xyz="0.0398145505519817 0 0.04"
      rpy="0 0 1.5708" />
    <parent
      link="base_link" />
    <child
      link="base_lidar_link" />
    <axis
      xyz="0 0 0" />
  </joint>
</robot>